<?xml version="1.0" ?>

<robot name="canopies" xmlns:xacro="http://ros.org/wiki/xacro">

  <!-- File includes -->
  <xacro:include filename="$(find canopies_description)/urdf/torso/torso.transmission.xacro" />


  <!-- Torso macro -->
  <xacro:macro name="canopies_torso" params="name parent">

  <!-- Torso yaw -->
  <link
    name="${name}_yaw_link">
    <inertial>
      <origin
        xyz="-2.65609177871329E-05 -0.000435786406406857 0.00668095998040263"
        rpy="0 0 0" />
      <mass
        value="3.08062751553524" />
      <inertia
        ixx="0.0118287754267984"
        ixy="-7.53330500953443E-06"
        ixz="1.67448680288092E-07"
        iyy="0.0118749837139915"
        iyz="-1.81778403003434E-07"
        izz="0.0235557708250256" />
    </inertial>
    <visual>
      <origin
        xyz="0 0 0"
        rpy="0 0 0" />
      <geometry>
        <mesh
          filename="package://canopies_description/meshes/torso_yaw.STL" />
      </geometry>
      <material
        name="">
        <color
          rgba="0.752941176470588 0.752941176470588 0.752941176470588 1" />
      </material>
  </visual>
    <collision>
      <origin
        xyz="0 0 0"
        rpy="0 0 0" />
      <geometry>
        <mesh
          filename="package://canopies_description/meshes/torso_yaw_convex.STL" />
      </geometry>
    </collision>
  </link>
  <joint
    name="${name}_yaw_joint"
    type="revolute">
    <origin
      xyz="0 0 0.144"
      rpy="0 0 0" />
    <parent
      link="${parent}" />
    <child
      link="${name}_yaw_link" />
    <axis
      xyz="0 0 1" />
    <limit
      lower="-3.0107"
      upper="3.0107"
      effort="2000"
      velocity="2" />
  </joint>

  <!-- Torso fix -->
  <link
    name="${name}_fix_link">
    <inertial>
      <origin
        xyz="0.0252969404404609 -0.0103776216172753 0.20112908638825"
        rpy="0 0 0" />
      <mass
        value="11.1069753304074" />
      <inertia
        ixx="0.163309283241266"
        ixy="5.03933214554739E-05"
        ixz="-0.0040119335221245"
        iyy="0.161417347213433"
        iyz="-0.000559120248100301"
        izz="0.0394165396913767" />
    </inertial>
    <visual>
      <origin
        xyz="0 0 0"
        rpy="0 0 0" />
      <geometry>
        <mesh filename="package://canopies_description/meshes/torso_fix.STL" />
      </geometry>
      <material
        name="">
        <color
          rgba="0.752941176470588 0.752941176470588 0.752941176470588 1" />
      </material>
    </visual>
    <collision>
      <origin
        xyz="0 0 0"
        rpy="0 0 0" />
      <geometry>
        <mesh
          filename="package://canopies_description/meshes/torso_fix_convex.STL" />
      </geometry>
    </collision>
  </link>
  <joint
    name="${name}_fix_joint"
    type="fixed">
    <origin
      xyz="0 0 0.0165"
      rpy="0 0 0" />
    <parent
      link="${name}_yaw_link" />
    <child
      link="${name}_fix_link" />
    <axis
      xyz="0 0 0" />
  </joint>

   <!-- Middle extending  -->
  <link name="${name}_fixed_column_link">
    <inertial>
      <origin rpy="0 0 0" xyz="0 0 0" />
      <mass value="0.01" />
      <inertia ixx="0.000001" ixy="0" ixz="0"
               iyy="0.000001" iyz="0"
               izz="0.000001" />
    </inertial>
    <visual>
      <origin rpy="0 0 0" xyz="0 0 0.275" />
      <geometry>
        <box size="0.18 0.2 0.55"/>
      </geometry>
      <material name="DarkGrey"/>
    </visual>
    <collision>
      <origin rpy="0 0 0" xyz="0 0 0.275" />
      <geometry>
        <box size="0.23 0.23 0.55"/>
      </geometry>
      <material name="DarkGrey"/>
    </collision>
  </link>
  <gazebo reference="${name}_fixed_column_link">
    <material>Gazebo/DarkGrey</material>
  </gazebo>

  <joint name="${name}_fixed_column_joint" type="fixed">
    <origin rpy="0 0 0" xyz="0.025 0 0.195" />
    <parent link="${parent}" />
    <child link="${name}_fixed_column_link" />
    <axis xyz="0 0 0" />
  </joint>

  <!-- Torso lift -->
  <link
    name="${name}_lift_link">
    <inertial>
      <origin
        xyz="0.101990394145162 0.000680984177382946 -0.115643554033635"
        rpy="0 0 0" />
      <mass
        value="10.1808989814849" />
      <inertia
        ixx="0.146245909179038"
        ixy="-1.46847178715372E-05"
        ixz="-0.00560071984192646"
        iyy="0.126819752699149"
        iyz="-0.000566234960303349"
        izz="0.058050729772705" />
    </inertial>
    <visual>
      <origin
        xyz="0 0 0"
        rpy="0 0 0" />
      <geometry>
        <mesh
          filename="package://canopies_description/meshes/torso_lift.STL" />
      </geometry>
      <material
        name="">
        <color
          rgba="0.792156862745098 0.819607843137255 0.933333333333333 1" />
      </material>
    </visual>
    <collision>
      <origin
        xyz="0 0 0"
        rpy="0 0 0" />
      <geometry>
        <mesh
          filename="package://canopies_description/meshes/torso_lift_convex.STL" />
      </geometry>
    </collision>
  </link>
  <joint
    name="${name}_lift_joint"
    type="prismatic">
    <origin
      xyz="0 0 0.606"
      rpy="0 0 0" />
    <parent
      link="${name}_fix_link" />
    <child
      link="${name}_lift_link" />
    <axis
      xyz="0 0 1" />
    <limit
      lower="0"
      upper="0.35"
      effort="2000"
      velocity="0.07" />
  </joint>

  <!-- Transmissions -->
  <xacro:torso_simple_transmission name="torso_yaw"  reduction="1.0"/>
  <xacro:torso_simple_transmission name="torso_lift" reduction="1.0"/>
 
  </xacro:macro>

</robot>
